2023-10-16 19:07:08,298 DEBUG    root            Loaded Command Group: ['gcloud', 'compute']
2023-10-16 19:07:08,313 DEBUG    root            Loaded Command Group: ['gcloud', 'compute', 'ssh']
2023-10-16 19:07:08,316 DEBUG    root            Running [gcloud.compute.ssh] with arguments: [[USER@]INSTANCE: "list"]
2023-10-16 19:07:08,341 DEBUG    google.auth.transport.requests Making request: POST https://oauth2.googleapis.com/token
2023-10-16 19:07:08,342 DEBUG    urllib3.connectionpool Starting new HTTPS connection (1): oauth2.googleapis.com:443
2023-10-16 19:07:08,467 DEBUG    urllib3.connectionpool https://oauth2.googleapis.com:443 "POST /token HTTP/1.1" 400 None
2023-10-16 19:07:08,468 DEBUG    google.auth.transport.requests Making request: POST https://oauth2.googleapis.com/token
2023-10-16 19:07:08,519 DEBUG    urllib3.connectionpool https://oauth2.googleapis.com:443 "POST /token HTTP/1.1" 400 None
2023-10-16 19:07:08,520 DEBUG    root            (gcloud.compute.ssh) There was a problem refreshing your current auth tokens: ('invalid_grant: Bad Request', {'error': 'invalid_grant', 'error_description': 'Bad Request'})
Please run:

  $ gcloud auth login

to obtain new credentials.

If you have already logged in with a different account, run:

  $ gcloud config set account ACCOUNT

to select an already authenticated account to use.
Traceback (most recent call last):
  File "/usr/lib/google-cloud-sdk/lib/googlecloudsdk/core/util/retry.py", line 307, in DecoratedFunction
    return retryer.RetryOnException(f, args=args, kwargs=kwargs,
  File "/usr/lib/google-cloud-sdk/lib/googlecloudsdk/core/util/retry.py", line 197, in RetryOnException
    result, exc_info = self.RetryOnResult(
  File "/usr/lib/google-cloud-sdk/lib/googlecloudsdk/core/util/retry.py", line 256, in RetryOnResult
    self._RaiseIfStop(result, state)
  File "/usr/lib/google-cloud-sdk/lib/googlecloudsdk/core/util/retry.py", line 115, in _RaiseIfStop
    raise MaxRetrialsException('Reached', result, state)
googlecloudsdk.core.util.retry.MaxRetrialsException: last_result=(None, (<class 'google.auth.exceptions.RefreshError'>, RefreshError('invalid_grant: Bad Request', {'error': 'invalid_grant', 'error_description': 'Bad Request'}), <traceback object at 0x7fcd913a7cc0>)), last_retrial=1, time_passed_ms=179,time_to_wait=0

During handling of the above exception, another exception occurred:

Traceback (most recent call last):
  File "/usr/lib/google-cloud-sdk/lib/googlecloudsdk/core/credentials/store.py", line 847, in HandleGoogleAuthCredentialsRefreshError
    yield
  File "/usr/lib/google-cloud-sdk/lib/googlecloudsdk/core/credentials/store.py", line 960, in _RefreshGoogleAuth
    credentials.refresh(request_client)
  File "/usr/lib/google-cloud-sdk/lib/googlecloudsdk/core/credentials/creds.py", line 641, in _WrappedRefresh
    orig_refresh(request)
  File "/usr/lib/google-cloud-sdk/lib/googlecloudsdk/core/credentials/google_auth_credentials.py", line 105, in refresh
    return self._Refresh(request)
  File "/usr/lib/google-cloud-sdk/lib/googlecloudsdk/core/credentials/google_auth_credentials.py", line 150, in _Refresh
    access_token, refresh_token, expiry, grant_response = _RefreshGrant(
  File "/usr/lib/google-cloud-sdk/lib/googlecloudsdk/core/credentials/google_auth_credentials.py", line 245, in _RefreshGrant
    response_data = _TokenEndpointRequestWithRetry(request, token_uri, body)
  File "/usr/lib/google-cloud-sdk/lib/googlecloudsdk/core/util/retry.py", line 312, in DecoratedFunction
    exceptions.reraise(to_reraise[1], tb=to_reraise[2])
  File "/usr/lib/google-cloud-sdk/lib/googlecloudsdk/core/exceptions.py", line 146, in reraise
    six.reraise(type(exc_value), exc_value, tb)
  File "/usr/bin/../lib/google-cloud-sdk/lib/third_party/six/__init__.py", line 719, in reraise
    raise value
  File "/usr/lib/google-cloud-sdk/lib/googlecloudsdk/core/util/retry.py", line 182, in TryFunc
    return func(*args, **kwargs), None
  File "/usr/lib/google-cloud-sdk/lib/googlecloudsdk/core/credentials/google_auth_credentials.py", line 306, in _TokenEndpointRequestWithRetry
    _HandleErrorResponse(response_body)
  File "/usr/lib/google-cloud-sdk/lib/googlecloudsdk/core/credentials/google_auth_credentials.py", line 335, in _HandleErrorResponse
    google_auth_client._handle_error_response(error_data, False)  # pylint: disable=protected-access
  File "/usr/bin/../lib/google-cloud-sdk/lib/third_party/google/oauth2/_client.py", line 72, in _handle_error_response
    raise exceptions.RefreshError(
google.auth.exceptions.RefreshError: ('invalid_grant: Bad Request', {'error': 'invalid_grant', 'error_description': 'Bad Request'})

During handling of the above exception, another exception occurred:

Traceback (most recent call last):
  File "/usr/lib/google-cloud-sdk/lib/googlecloudsdk/calliope/cli.py", line 987, in Execute
    resources = calliope_command.Run(cli=self, args=args)
  File "/usr/lib/google-cloud-sdk/lib/googlecloudsdk/calliope/backend.py", line 807, in Run
    resources = command_instance.Run(args)
  File "/usr/lib/google-cloud-sdk/lib/surface/compute/ssh.py", line 266, in Run
    client = holder.client
  File "/usr/lib/google-cloud-sdk/lib/googlecloudsdk/api_lib/compute/base_classes.py", line 67, in client
    self._client = client_adapter.ClientAdapter(
  File "/usr/lib/google-cloud-sdk/lib/googlecloudsdk/api_lib/compute/client_adapter.py", line 71, in __init__
    self._client = client or core_apis.GetClientInstance(
  File "/usr/lib/google-cloud-sdk/lib/googlecloudsdk/api_lib/util/apis.py", line 265, in GetClientInstance
    return apis_internal._GetClientInstance(
  File "/usr/lib/google-cloud-sdk/lib/googlecloudsdk/api_lib/util/apis_internal.py", line 169, in _GetClientInstance
    http_client = transports.GetApitoolsTransport(
  File "/usr/lib/google-cloud-sdk/lib/googlecloudsdk/core/credentials/transports.py", line 80, in GetApitoolsTransport
    session = requests.GetSession(
  File "/usr/lib/google-cloud-sdk/lib/googlecloudsdk/core/credentials/requests.py", line 82, in GetSession
    session = request_wrapper.WrapQuota(session, enable_resource_quota,
  File "/usr/lib/google-cloud-sdk/lib/googlecloudsdk/core/credentials/requests.py", line 127, in WrapQuota
    quota_project = self.QuotaProject(enable_resource_quota,
  File "/usr/lib/google-cloud-sdk/lib/googlecloudsdk/core/credentials/transport.py", line 54, in QuotaProject
    creds = store.LoadIfEnabled(allow_account_impersonation, use_google_auth)
  File "/usr/lib/google-cloud-sdk/lib/googlecloudsdk/core/credentials/store.py", line 456, in LoadIfEnabled
    return Load(
  File "/usr/lib/google-cloud-sdk/lib/googlecloudsdk/core/credentials/store.py", line 566, in Load
    cred = _Load(
  File "/usr/lib/google-cloud-sdk/lib/googlecloudsdk/core/credentials/store.py", line 748, in _Load
    RefreshIfAlmostExpire(cred)
  File "/usr/lib/google-cloud-sdk/lib/googlecloudsdk/core/credentials/store.py", line 1069, in RefreshIfAlmostExpire
    RefreshIfExpireWithinWindow(credentials, window=_CREDENTIALS_EXPIRY_WINDOW)
  File "/usr/lib/google-cloud-sdk/lib/googlecloudsdk/core/credentials/store.py", line 1065, in RefreshIfExpireWithinWindow
    Refresh(credentials)
  File "/usr/lib/google-cloud-sdk/lib/googlecloudsdk/core/credentials/store.py", line 788, in Refresh
    _RefreshGoogleAuth(credentials, is_impersonated_credential,
  File "/usr/lib/google-cloud-sdk/lib/googlecloudsdk/core/credentials/store.py", line 960, in _RefreshGoogleAuth
    credentials.refresh(request_client)
  File "/usr/lib/google-cloud-sdk/platform/bundledpythonunix/lib/python3.9/contextlib.py", line 137, in __exit__
    self.gen.throw(typ, value, traceback)
  File "/usr/lib/google-cloud-sdk/lib/googlecloudsdk/core/credentials/store.py", line 856, in HandleGoogleAuthCredentialsRefreshError
    raise creds_exceptions.TokenRefreshError(six.text_type(e), for_adc=for_adc)
googlecloudsdk.core.credentials.exceptions.TokenRefreshError: There was a problem refreshing your current auth tokens: ('invalid_grant: Bad Request', {'error': 'invalid_grant', 'error_description': 'Bad Request'})
Please run:

  $ gcloud auth login

to obtain new credentials.

If you have already logged in with a different account, run:

  $ gcloud config set account ACCOUNT

to select an already authenticated account to use.
2023-10-16 19:07:08,523 ERROR    root            (gcloud.compute.ssh) There was a problem refreshing your current auth tokens: ('invalid_grant: Bad Request', {'error': 'invalid_grant', 'error_description': 'Bad Request'})
Please run:

  $ gcloud auth login

to obtain new credentials.

If you have already logged in with a different account, run:

  $ gcloud config set account ACCOUNT

to select an already authenticated account to use.
